[2025-02-25 13:57:52 +0000] [4601] [INFO] Starting gunicorn 23.0.0
[2025-02-25 13:57:52 +0000] [4601] [INFO] Listening at: http://0.0.0.0:5000 (4601)
[2025-02-25 13:57:52 +0000] [4601] [INFO] Using worker: sync
[2025-02-25 13:57:52 +0000] [4602] [INFO] Booting worker with pid: 4602
[2025-02-25 13:58:22 +0000] [4604] [INFO] Starting gunicorn 23.0.0
[2025-02-25 13:58:22 +0000] [4604] [ERROR] Connection in use: ('0.0.0.0', 5000)
[2025-02-25 13:58:22 +0000] [4604] [ERROR] connection to ('0.0.0.0', 5000) failed: [Errno 98] Address already in use
[2025-02-25 13:58:23 +0000] [4604] [ERROR] Connection in use: ('0.0.0.0', 5000)
[2025-02-25 13:58:23 +0000] [4604] [ERROR] connection to ('0.0.0.0', 5000) failed: [Errno 98] Address already in use
[2025-02-25 13:58:24 +0000] [4604] [ERROR] Connection in use: ('0.0.0.0', 5000)
[2025-02-25 13:58:24 +0000] [4604] [ERROR] connection to ('0.0.0.0', 5000) failed: [Errno 98] Address already in use
[2025-02-25 13:58:24 +0000] [4601] [CRITICAL] WORKER TIMEOUT (pid:4602)
[2025-02-25 13:58:24 +0000] [4602] [ERROR] Error handling request (no URI read)
Traceback (most recent call last):
  File "/home/ubuntu/cv-generator-backend/venv/lib/python3.12/site-packages/gunicorn/workers/sync.py", line 133, in handle
    req = next(parser)
          ^^^^^^^^^^^^
  File "/home/ubuntu/cv-generator-backend/venv/lib/python3.12/site-packages/gunicorn/http/parser.py", line 41, in __next__
    self.mesg = self.mesg_class(self.cfg, self.unreader, self.source_addr, self.req_count)
                ^^^^^^^^^^^^^^^^^^^^^^^^^^^^^^^^^^^^^^^^^^^^^^^^^^^^^^^^^^^^^^^^^^^^^^^^^^
  File "/home/ubuntu/cv-generator-backend/venv/lib/python3.12/site-packages/gunicorn/http/message.py", line 259, in __init__
    super().__init__(cfg, unreader, peer_addr)
  File "/home/ubuntu/cv-generator-backend/venv/lib/python3.12/site-packages/gunicorn/http/message.py", line 60, in __init__
    unused = self.parse(self.unreader)
             ^^^^^^^^^^^^^^^^^^^^^^^^^
  File "/home/ubuntu/cv-generator-backend/venv/lib/python3.12/site-packages/gunicorn/http/message.py", line 271, in parse
    self.get_data(unreader, buf, stop=True)
  File "/home/ubuntu/cv-generator-backend/venv/lib/python3.12/site-packages/gunicorn/http/message.py", line 262, in get_data
    data = unreader.read()
           ^^^^^^^^^^^^^^^
  File "/home/ubuntu/cv-generator-backend/venv/lib/python3.12/site-packages/gunicorn/http/unreader.py", line 36, in read
    d = self.chunk()
        ^^^^^^^^^^^^
  File "/home/ubuntu/cv-generator-backend/venv/lib/python3.12/site-packages/gunicorn/http/unreader.py", line 63, in chunk
    return self.sock.recv(self.mxchunk)
           ^^^^^^^^^^^^^^^^^^^^^^^^^^^^
  File "/home/ubuntu/cv-generator-backend/venv/lib/python3.12/site-packages/gunicorn/workers/base.py", line 204, in handle_abort
    sys.exit(1)
SystemExit: 1
[2025-02-25 13:58:24 +0000] [4602] [INFO] Worker exiting (pid: 4602)
[2025-02-25 13:58:24 +0000] [4615] [INFO] Booting worker with pid: 4615
[2025-02-25 13:58:25 +0000] [4604] [ERROR] Connection in use: ('0.0.0.0', 5000)
[2025-02-25 13:58:25 +0000] [4604] [ERROR] connection to ('0.0.0.0', 5000) failed: [Errno 98] Address already in use
[2025-02-25 13:58:26 +0000] [4604] [ERROR] Connection in use: ('0.0.0.0', 5000)
[2025-02-25 13:58:26 +0000] [4604] [ERROR] connection to ('0.0.0.0', 5000) failed: [Errno 98] Address already in use
[2025-02-25 13:58:27 +0000] [4604] [ERROR] Can't connect to ('0.0.0.0', 5000)
[2025-02-25 13:58:52 +0000] [4601] [INFO] Handling signal: int
[2025-02-25 13:58:52 +0000] [4615] [INFO] Worker exiting (pid: 4615)
[2025-02-25 13:58:53 +0000] [4601] [INFO] Shutting down: Master
[2025-02-25 13:59:16 +0000] [4617] [INFO] Starting gunicorn 23.0.0
[2025-02-25 13:59:16 +0000] [4617] [INFO] Listening at: http://0.0.0.0:5000 (4617)
[2025-02-25 13:59:16 +0000] [4617] [INFO] Using worker: sync
[2025-02-25 13:59:16 +0000] [4620] [INFO] Booting worker with pid: 4620
[2025-02-25 13:59:22 +0000] [4628] [INFO] Starting gunicorn 23.0.0
[2025-02-25 13:59:22 +0000] [4628] [ERROR] Connection in use: ('0.0.0.0', 5000)
[2025-02-25 13:59:22 +0000] [4628] [ERROR] connection to ('0.0.0.0', 5000) failed: [Errno 98] Address already in use
[2025-02-25 13:59:23 +0000] [4628] [ERROR] Connection in use: ('0.0.0.0', 5000)
[2025-02-25 13:59:23 +0000] [4628] [ERROR] connection to ('0.0.0.0', 5000) failed: [Errno 98] Address already in use
[2025-02-25 13:59:24 +0000] [4628] [ERROR] Connection in use: ('0.0.0.0', 5000)
[2025-02-25 13:59:24 +0000] [4628] [ERROR] connection to ('0.0.0.0', 5000) failed: [Errno 98] Address already in use
[2025-02-25 13:59:25 +0000] [4628] [ERROR] Connection in use: ('0.0.0.0', 5000)
[2025-02-25 13:59:25 +0000] [4628] [ERROR] connection to ('0.0.0.0', 5000) failed: [Errno 98] Address already in use
[2025-02-25 13:59:26 +0000] [4628] [ERROR] Connection in use: ('0.0.0.0', 5000)
[2025-02-25 13:59:26 +0000] [4628] [ERROR] connection to ('0.0.0.0', 5000) failed: [Errno 98] Address already in use
[2025-02-25 13:59:27 +0000] [4628] [ERROR] Can't connect to ('0.0.0.0', 5000)
[2025-02-25 14:00:11 +0000] [4617] [CRITICAL] WORKER TIMEOUT (pid:4620)
[2025-02-25 14:00:11 +0000] [4620] [ERROR] Error handling request (no URI read)
Traceback (most recent call last):
  File "/home/ubuntu/cv-generator-backend/venv/lib/python3.12/site-packages/gunicorn/workers/sync.py", line 133, in handle
    req = next(parser)
          ^^^^^^^^^^^^
  File "/home/ubuntu/cv-generator-backend/venv/lib/python3.12/site-packages/gunicorn/http/parser.py", line 41, in __next__
    self.mesg = self.mesg_class(self.cfg, self.unreader, self.source_addr, self.req_count)
                ^^^^^^^^^^^^^^^^^^^^^^^^^^^^^^^^^^^^^^^^^^^^^^^^^^^^^^^^^^^^^^^^^^^^^^^^^^
  File "/home/ubuntu/cv-generator-backend/venv/lib/python3.12/site-packages/gunicorn/http/message.py", line 259, in __init__
    super().__init__(cfg, unreader, peer_addr)
  File "/home/ubuntu/cv-generator-backend/venv/lib/python3.12/site-packages/gunicorn/http/message.py", line 60, in __init__
    unused = self.parse(self.unreader)
             ^^^^^^^^^^^^^^^^^^^^^^^^^
  File "/home/ubuntu/cv-generator-backend/venv/lib/python3.12/site-packages/gunicorn/http/message.py", line 271, in parse
    self.get_data(unreader, buf, stop=True)
  File "/home/ubuntu/cv-generator-backend/venv/lib/python3.12/site-packages/gunicorn/http/message.py", line 262, in get_data
    data = unreader.read()
           ^^^^^^^^^^^^^^^
  File "/home/ubuntu/cv-generator-backend/venv/lib/python3.12/site-packages/gunicorn/http/unreader.py", line 36, in read
    d = self.chunk()
        ^^^^^^^^^^^^
  File "/home/ubuntu/cv-generator-backend/venv/lib/python3.12/site-packages/gunicorn/http/unreader.py", line 63, in chunk
    return self.sock.recv(self.mxchunk)
           ^^^^^^^^^^^^^^^^^^^^^^^^^^^^
  File "/home/ubuntu/cv-generator-backend/venv/lib/python3.12/site-packages/gunicorn/workers/base.py", line 204, in handle_abort
    sys.exit(1)
SystemExit: 1
[2025-02-25 14:00:11 +0000] [4620] [INFO] Worker exiting (pid: 4620)
[2025-02-25 14:00:11 +0000] [4632] [INFO] Booting worker with pid: 4632
[2025-02-26 02:10:45 +0000] [4632] [WARNING] Invalid request from ip=66.132.159.253: Invalid HTTP Version: (2, 0)
[2025-02-26 08:07:01 +0000] [4617] [CRITICAL] WORKER TIMEOUT (pid:4632)
[2025-02-26 08:24:54 +0000] [4617] [ERROR] Worker (pid:4632) was sent SIGKILL! Perhaps out of memory?
[2025-02-26 08:24:55 +0000] [7456] [INFO] Booting worker with pid: 7456
[2025-02-26 13:45:47 +0000] [4617] [CRITICAL] WORKER TIMEOUT (pid:7456)
[2025-02-26 13:47:16 +0000] [4617] [ERROR] Worker (pid:7456) was sent SIGKILL! Perhaps out of memory?
[2025-02-26 13:47:18 +0000] [7905] [INFO] Booting worker with pid: 7905
[2025-02-27 11:56:51 +0000] [4617] [CRITICAL] WORKER TIMEOUT (pid:7905)
[2025-02-27 11:58:24 +0000] [4617] [ERROR] Worker (pid:7905) was sent SIGKILL! Perhaps out of memory?
[2025-02-27 11:58:25 +0000] [27846] [INFO] Booting worker with pid: 27846
[2025-02-27 12:21:17 +0000] [4617] [CRITICAL] WORKER TIMEOUT (pid:27846)
[2025-02-27 12:25:58 +0000] [4617] [ERROR] Worker (pid:27846) was sent SIGKILL! Perhaps out of memory?
[2025-02-27 12:26:00 +0000] [28208] [INFO] Booting worker with pid: 28208
[2025-02-27 21:15:30 +0000] [4617] [CRITICAL] WORKER TIMEOUT (pid:28208)
[2025-02-27 21:16:55 +0000] [4617] [ERROR] Worker (pid:28208) was sent SIGKILL! Perhaps out of memory?
[2025-02-27 21:16:57 +0000] [32673] [INFO] Booting worker with pid: 32673
[2025-03-01 02:24:47 +0000] [4617] [ERROR] Worker (pid:32673) was sent SIGHUP!
[2025-03-01 02:24:48 +0000] [4617] [INFO] Handling signal: term
[2025-03-01 02:24:48 +0000] [49366] [INFO] Booting worker with pid: 49366
[2025-03-01 02:25:18 +0000] [4617] [INFO] Shutting down: Master
